Workbook

Sheet README
A1: NEURO-METRO: AVUI — GAME CONFIG
A3: This workbook is the source of truth for all game content. The prototype reads no
A4: content values of its own — every number, ability, unit and rule comes from here.
A6: HOW THE ROUND TRIP WORKS
A7: 1. Edit any sheet in Google Sheets.
A8: 2. File > Download > Comma-separated values, one CSV per sheet.
A9: 3. Put the CSVs in a folder and run: python3 tools/build_data.py <folder>
A10: 4. That regenerates data.js. Reload the prototype. Nothing else to touch.
A12: COLUMN STATUS — the row under each header
A13: LIVE (green) the prototype reads this column today. Renaming it breaks the game.
A14: planned (yellow) reserved for design you have not built yet. Inert until wired up;
A15: safe to fill in early. Tell me when you want one activated.
... A44: checks live validation. Every row should read OK.

Sheet emotions
A1: One row per emotional type. 'token' is the CSS palette variable name; 'hex' drives every colour in the UI for this emotion; 'bg_hex' tints the battle backdrop when an enemy of this type is fought.
A3: id | B3: name | C3: token | D3: hex | E3: bg_hex | F3: short | G3: icon | H3: sfx | I3: description | J3: enabled | K3: notes
A4: LIVE | B4: LIVE | C4: LIVE | D4: LIVE | E4: LIVE | F4: planned | G4: LIVE | H4: LIVE | I4: planned | J4: planned | K4: planned
A5: ANGER | B5: Anger | C5: anger | D5: #e53859 | E5: #2a0810 | F5: ANG | G5: BOLT | H5: hit_anger | I5: Hot, direct, aggressive. | J5: 1
A6: SURPRISE | B6: Surprise | C6: surprise | D6: #724082 | E6: #170a1b | F6: SUR | G6: BURST | H6: hit_surprise | I6: Sudden, disruptive, disorienting. | J6: 1
A7: DISGUST | B7: Disgust | C7: disgust | D7: #56a36a | E7: #0c1f13 | F7: DIS | G7: ROT | H7: hit_disgust | I7: Rejecting, corrosive, contemptuous. | J7: 1
A8: JOY | B8: Joy | C8: joy | D8: #fcc336 | E8: #2a1f06 | F8: JOY | G8: SPARK | H8: hit_joy | I8: Bright, volatile, energising. | J8: 1
A9: SADNESS | B9: Sadness | C9: sadness | D9: #3d66c1 | E9: #0a1229 | F9: SAD | G9: DROP | H9: hit_sadness | I9: Heavy, draining, persistent. | J9: 1
A10: FEAR | B10: Fear | C10: fear | D10: #929fa5 | E10: #1a1e20 | F10: FEA | G10: EYE | H10: hit_fear | I10: Cold, freezing, evasive. | J10: 1

Sheet abilities
A1: One row per ability. kind: DAMAGE | SHIELD (add more kinds as you design them). power = damage for DAMAGE, shield charges for SHIELD. Leave 'emotion' blank for typeless — a typeless ability never matches a layer. 'suggested_cost' is a formula: a costing sanity check, not a rule.
A3: id | B3: name | C3: emotion | D3: cost | E3: kind | F3: power | G3: charge | H3: hits_layer | I3: icon | J3: target | K3: reach | L3: self_ms | M3: self_ec | N3: ec_push_target | O3: ec_drain_target | P3: heal | Q3: shield_gain | R3: pierce_shield | S3: ignore_layer | T3: repeat | U3: cooldown | V3: uses | W3: blurb | X3: action | Y3: emotions | Z3: crit_chance | AA3: status_apply | AB3: status_chance | AC3: status_duration | AD3: combo_tag | AE3: requires_prev_tag | AF3: synergy_group | AG3: wild_target | AH3: rarity | AI3: unlock | AJ3: enabled | AK3: suggested_cost | AL3: cost_delta | AM3: notes
A4: LIVE | B4: LIVE | C4: LIVE | D4: LIVE | E4: LIVE | F4: LIVE | G4: LIVE | H4: LIVE | I4: LIVE | J4: planned | K4: planned | L4: LIVE | M4: planned | N4: planned | O4: planned | P4: planned | Q4: planned | R4: planned | S4: planned | T4: planned | U4: LIVE | V4: LIVE | W4: LIVE | X4: LIVE | Y4: LIVE | Z4: LIVE | AA4: LIVE | AB4: planned | AC4: LIVE | AD4: planned | AE4: planned | AF4: planned | AG4: planned | AH4: planned | AI4: planned | AJ4: planned | AK4: planned | AL4: planned | AM4: planned
A5: ATK_ANGER | B5: Heated Punch | C5: ANGER | D5: 20 | E5: DAMAGE | F5: 35 | G5: 0 | H5: 1 | I5: BOLT | J5: ENEMY | K5: SINGLE | L5: 0 | M5: 0 | N5: 0 | O5: 0 | P5: 0 | Q5: 0 | R5: 0 | S5: 0 | T5: 1 | U5: 1 | V5: 3 | W5: Attack. Cracks the outermost {LAYER}. | X5: 0 | AB5: 0 | AC5: 0 | AG5: LOWEST_MS | AH5: COMMON | AJ5: 1 | AK5: =ROUND(G5*0.6 + N5*0.4 + P5*0.7 + Q5*8 + ABS(L5)*0.3, 0) | AL5: =IFERROR(D5-AG5,"")
A6: ATK_SADNESS | B6: Cold Shoulder | C6: SADNESS | D6: 20 | E6: DAMAGE | F6: 35 | G6: 0 | H6: 1 | I6: DROP | J6: ENEMY | K6: SINGLE | L6: 0 | M6: 0 | N6: 0 | O6: 0 | P6: 0 | Q6: 0 | R6: 0 | S6: 0 | T6: 1 | U6: 1 | V6: 3 | W6: Attack. Cracks the outermost {LAYER}. | X6: 0 | AB6: 0 | AC6: 0 | AG6: LOWEST_MS | AH6: COMMON | AJ6: 1 | AK6: =ROUND(G6*0.6 + N6*0.4 + P6*0.7 + Q6*8 + ABS(L6)*0.3, 0) | AL6: =IFERROR(D6-AG6,"")
A7: ATK_JOY | B7: Manic Grin | C7: JOY | D7: 20 | E7: DAMAGE | F7: 35 | G7: 0 | H7: 1 | I7: SPARK | J7: ENEMY | K7: SINGLE | L7: 0 | M7: 0 | N7: 0 | O7: 0 | P7: 0 | Q7: 0 | R7: 0 | S7: 0 | T7: 1 | U7: 1 | V7: 3 | W7: Attack. Cracks the outermost {LAYER}. | X7: 0 | AB7: 0 | AC7: 0 | AG7: LOWEST_MS | AH7: COMMON | AJ7: 1 | AK7: =ROUND(G7*0.6 + N7*0.4 + P7*0.7 + Q7*8 + ABS(L7)*0.3, 0) | AL7: =IFERROR(D7-AG7,"")
A8: DEFEND | B8: Block | D8: 10 | E8: SHIELD | F8: 1 | G8: 0 | H8: 0 | I8: SHIELD | J8: SELF | K8: SINGLE | L8: 0 | M8: 0 | N8: 0 | O8: 0 | P8: 0 | Q8: 1 | R8: 0 | S8: 0 | T8: 1 | U8: 1 | V8: 3 | W8: Defence. Blocks the next hit outright. | X8: 1 | AB8: 0 | AC8: 0 | AG8: SELF | AH8: COMMON | AJ8: 1 | AK8: =ROUND(G8*0.6 + N8*0.4 + P8*0.7 + Q8*8 + ABS(L8)*0.3, 0) | AL8: =IFERROR(D8-AG8,"")
A9: HVY_ANGER | B9: Rage | C9: ANGER | D9: 45 | E9: DAMAGE | F9: 90 | G9: 2 | H9: 1 | I9: BOLT | J9: ENEMY | K9: SINGLE | L9: 0 | M9: 0 | N9: 0 | O9: 0 | P9: 0 | Q9: 0 | R9: 0 | S9: 0 | T9: 1 | U9: 1 | V9: 2 | W9: Attack. *Charges* first, then hits for triple. | X9: 0 | AB9: 0 | AC9: 0 | AG9: LOWEST_MS | AH9: COMMON | AJ9: 1 | AK9: =ROUND(G9*0.6 + N9*0.4 + P9*0.7 + Q9*8 + ABS(L9)*0.3, 0) | AL9: =IFERROR(D9-AG9,"")
A10: HVY_SADNESS | B10: Grief | C10: SADNESS | D10: 45 | E10: DAMAGE | F10: 90 | G10: 2 | H10: 1 | I10: DROP | J10: ENEMY | K10: SINGLE | L10: 0 | M10: 0 | N10: 0 | O10: 0 | P10: 0 | Q10: 0 | R10: 0 | S10: 0 | T10: 1 | U10: 1 | V10: 2 | W10: Attack. *Charges* first, then hits for triple. | X10: 0 | AB10: 0 | AC10: 0 | AG10: LOWEST_MS | AH10: COMMON | AJ10: 1 | AK10: =ROUND(G10*0.6 + N10*0.4 + P10*0.7 + Q10*8 + ABS(L10)*0.3, 0) | AL10: =IFERROR(D10-AG10,"")
A11: HVY_JOY | B11: Mania | C11: JOY | D11: 60 | E11: DAMAGE | F11: 130 | G11: 3 | H11: 1 | I11: SPARK | J11: ENEMY | K11: SINGLE | L11: 0 | M11: 0 | N11: 0 | O11: 0 | P11: 0 | Q11: 0 | R11: 0 | S11: 0 | T11: 1 | U11: 1 | V11: 2 | W11: Attack. The hardest hit there is, after a long *charge*. | X11: 0 | AB11: 0 | AC11: 0 | AG11: LOWEST_MS | AH11: COMMON | AJ11: 1 | AK11: =ROUND(G11*0.6 + N11*0.4 + P11*0.7 + Q11*8 + ABS(L11)*0.3, 0) | AL11: =IFERROR(D11-AG11,"")
A12: RECHARGE | B12: Recharge | D12: 0 | E12: CHARGE | F12: 20 | G12: 0 | H12: 0 | I12: CHARGE | J12: SELF | K12: SINGLE | L12: 5 | M12: 0 | N12: 0 | O12: 0 | P12: 0 | Q12: 0 | R12: 0 | S12: 0 | T12: 1 | U12: 1 | V12: 3 | W12: Buff. Trades your own {MS} for {EC}. | X12: 1 | AB12: 0 | AC12: 0 | AG12: SELF | AH12: COMMON | AJ12: 1 | AK12: =ROUND(G12*0.6 + N12*0.4 + P12*0.7 + Q12*8 + ABS(L12)*0.3, 0) | AL12: =IFERROR(D12-AG12,"") | AM12: Gains 20 EC and costs 5 of your own MS — which also lowers your ceiling.
A13: GEN_DISGUST | B13: Bile | C13: DISGUST | D13: 15 | E13: ADDLAYER | F13: 1 | G13: 0 | H13: 0 | I13: ROT | J13: SELF | K13: SINGLE | L13: 0 | M13: 0 | N13: 0 | O13: 0 | P13: 0 | Q13: 0 | R13: 0 | S13: 0 | T13: 1 | U13: 1 | V13: 2 | W13: Defence. Grows a {LAYER} that *never regrows* once broken. | X13: 0 | AB13: 0 | AC13: 0 | AG13: SELF | AH13: COMMON | AJ13: 1 | AK13: =ROUND(G13*0.6 + N13*0.4 + P13*0.7 + Q13*8 + ABS(L13)*0.3, 0) | AL13: =IFERROR(D13-AG13,"") | AM13: Grows one extra Disgust layer. Grown layers are TEMPORARY: once broken they never regrow.
A14: GEN_ANGER | B14: Bristle | C14: ANGER | D14: 15 | E14: ADDLAYER | F14: 1 | G14: 0 | H14: 0 | I14: ROT | J14: SELF | K14: SINGLE | L14: 0 | M14: 0 | N14: 0 | O14: 0 | P14: 0 | Q14: 0 | R14: 0 | S14: 0 | T14: 1 | U14: 1 | V14: 2 | W14: Defence. Grows a {LAYER} that *never regrows* once broken. | X14: 0 | AB14: 0 | AC14: 0 | AG14: SELF | AH14: COMMON | AJ14: 1 | AK14: =ROUND(G14*0.6 + N14*0.4 + P14*0.7 + Q14*8 + ABS(L14)*0.3, 0) | AL14: =IFERROR(D14-AG14,"") | AM14: Grows one extra Anger layer. Grown layers are TEMPORARY: once broken they never regrow.
A15: GEN_JOY | B15: Good Vibes | C15: JOY | D15: 15 | E15: ADDLAYER | F15: 1 | G15: 0 | H15: 0 | I15: SPARK | J15: SELF | K15: SINGLE | L15: 0 | M15: 0 | N15: 0 | O15: 0 | P15: 0 | Q15: 0 | R15: 0 | S15: 0 | T15: 1 | U15: 1 | V15: 2 | W15: Defence. Grows a {LAYER} that *never regrows* once broken. | X15: 0 | AB15: 0 | AC15: 0 | AG15: SELF | AH15: COMMON | AJ15: 1 | AK15: =ROUND(G15*0.6 + N15*0.4 + P15*0.7 + Q15*8 + ABS(L15)*0.3, 0) | AL15: =IFERROR(D15-AG15,"") | AM15: Grows one extra Joy layer. Grown layers are TEMPORARY: once broken they never regrow.
A16: ROT | B16: Fester | C16: DISGUST | D16: 25 | E16: DEBUFF | F16: 0 | G16: 0 | H16: 0 | I16: ROT | J16: ENEMY | K16: SINGLE | L16: 0 | M16: 0 | N16: 0 | O16: 0 | P16: 0 | Q16: 0 | R16: 0 | S16: 0 | T16: 1 | U16: 1 | V16: 2 | W16: Debuff. Target cannot regrow *2* {LAYERS} for *2 turns*. | X16: 0 | AA16: NO_REGEN | AB16: 0 | AC16: 2 | AG16: LOWEST_MS | AH16: COMMON | AJ16: 1 | AK16: =ROUND(G16*0.6 + N16*0.4 + P16*0.7 + Q16*8 + ABS(L16)*0.3, 0) | AL16: =IFERROR(D16-AG16,"") | AM16: For 2 turns the target cannot regrow 2 of its broken layers.
A17: INFLICT_SAD | B17: Self-Harm | C17: SADNESS | D17: 30 | E17: DEBUFF | F17: 0 | G17: 0 | H17: 0 | I17: DROP | J17: ENEMY | K17: SINGLE | L17: 0 | M17: 0 | N17: 0 | O17: 0 | P17: 0 | Q17: 0 | R17: 0 | S17: 0 | T17: 1 | U17: 1 | V17: 2 | W17: Status. Target attacks *itself* each round for *2 turns*. | X17: 0 | AA17: SAD | AB17: 0 | AC17: 2 | AG17: LOWEST_MS | AH17: COMMON | AJ17: 1 | AK17: =ROUND(G17*0.6 + N17*0.4 + P17*0.7 + Q17*8 + ABS(L17)*0.3, 0) | AL17: =IFERROR(D17-AG17,"") | AM17: Each round end the target turns one of its own attacks on itself. NOTE: distinct from SELF_HARM, which is the Overload-forced station.
A18: BLIND | B18: Blinded by Hate | C18: ANGER | D18: 30 | E18: DEBUFF | F18: 0 | G18: 0 | H18: 0 | I18: EYE | J18: ENEMY | K18: SINGLE | L18: 0 | M18: 0 | N18: 0 | O18: 0 | P18: 0 | Q18: 0 | R18: 0 | S18: 0 | T18: 1 | U18: 1 | V18: 2 | W18: Debuff. Target *misses half* its attacks for *2 turns*. | X18: 0 | AA18: BLINDED | AB18: 0 | AC18: 2 | AG18: LOWEST_MS | AH18: COMMON | AJ18: 1 | AK18: =ROUND(G18*0.6 + N18*0.4 + P18*0.7 + Q18*8 + ABS(L18)*0.3, 0) | AL18: =IFERROR(D18-AG18,"") | AM18: ENEMY ability. The target misses half its attacks for 2 turns.
A19: ATK_SURPRISE | B19: Sucker Punch | C19: SURPRISE | D19: 20 | E19: DAMAGE | F19: 35 | G19: 0 | H19: 1 | I19: BURST | J19: ENEMY | K19: SINGLE | L19: 0 | M19: 0 | N19: 0 | O19: 0 | P19: 0 | Q19: 0 | R19: 0 | S19: 0 | T19: 1 | U19: 1 | V19: 3 | W19: Attack. Cracks the outermost {LAYER}. | X19: 0 | AB19: 0 | AC19: 0 | AG19: LOWEST_MS | AH19: COMMON | AJ19: 1 | AK19: =ROUND(G19*0.6 + N19*0.4 + P19*0.7 + Q19*8 + ABS(L19)*0.3, 0) | AL19: =IFERROR(D19-AG19,"")
A20: HVY_SURPRISE | B20: Whiplash | C20: SURPRISE | D20: 45 | E20: DAMAGE | F20: 90 | G20: 2 | H20: 1 | I20: BURST | J20: ENEMY | K20: SINGLE | L20: 0 | M20: 0 | N20: 0 | O20: 0 | P20: 0 | Q20: 0 | R20: 0 | S20: 0 | T20: 1 | U20: 1 | V20: 2 | W20: Attack. *Charges* first, then hits for triple. | X20: 0 | AB20: 0 | AC20: 0 | AG20: LOWEST_MS | AH20: COMMON | AJ20: 1 | AK20: =ROUND(G20*0.6 + N20*0.4 + P20*0.7 + Q20*8 + ABS(L20)*0.3, 0) | AL20: =IFERROR(D20-AG20,"")
A21: MID_SURPRISE | B21: Double Take | C21: SURPRISE | D21: 30 | E21: DAMAGE | F21: 60 | G21: 1 | H21: 1 | I21: BURST | J21: ENEMY | K21: SINGLE | L21: 0 | M21: 0 | N21: 0 | O21: 0 | P21: 0 | Q21: 0 | R21: 0 | S21: 0 | T21: 1 | U21: 1 | V21: 2 | W21: Attack. *Charges* once, then hits hard. | X21: 0 | AB21: 0 | AC21: 0 | AG21: LOWEST_MS | AH21: COMMON | AJ21: 1 | AK21: =ROUND(G21*0.6 + N21*0.4 + P21*0.7 + Q21*8 + ABS(L21)*0.3, 0) | AL21: =IFERROR(D21-AG21,"") | AM21: Between ATK_SURPRISE and HVY_SURPRISE in every respect: one charging station rather than none or two, and power to match. The Set of Jolt is built around it.
A22: STARTLE | B22: Out of Nowhere | C22: SURPRISE | D22: 25 | E22: DEBUFF | F22: 0 | G22: 0 | H22: 0 | I22: BURST | J22: ENEMY | K22: SINGLE | L22: 0 | M22: 0 | N22: 0 | O22: 0 | P22: 0 | Q22: 0 | R22: 0 | S22: 0 | T22: 1 | U22: 1 | V22: 2 | W22: Debuff. Target *misses a third* of its attacks for *2 turns*. | X22: 0 | AA22: RATTLED | AB22: 0 | AC22: 2 | AG22: LOWEST_MS | AH22: COMMON | AJ22: 1 | AK22: =ROUND(G22*0.6 + N22*0.4 + P22*0.7 + Q22*8 + ABS(L22)*0.3, 0) | AL22: =IFERROR(D22-AG22,"") | AM22: Surprise's debuff. Softer than BLIND and cheaper, because Surprise pays for it with a weaker basic economy rather than with a bigger bill.
A23: DRUG_HIT | B23: Drug Hit | C23: SURPRISE | D23: 20 | E23: DAMAGE | F23: 35 | G23: 0 | H23: 1 | I23: BURST | J23: ENEMY | K23: SINGLE | L23: 0 | M23: 0 | N23: 0 | O23: 0 | P23: 0 | Q23: 0 | R23: 0 | S23: 0 | T23: 1 | U23: 1 | V23: 3 | W23: Attack. Cracks the outermost {LAYER} and leaves them *Dizzy* for a turn. | X23: 0 | AA23: DIZZY | AB23: 0 | AC23: 1 | AG23: LOWEST_MS | AH23: COMMON | AJ23: 1 | AK23: =ROUND(G23*0.6 + N23*0.4 + P23*0.7 + Q23*8 + ABS(L23)*0.3, 0) | AL23: =IFERROR(D23-AG23,"") | AM23: Costed as a BASIC - exactly ATK_SURPRISE's cost and power - because Dizzy lasts one turn and is a coin flip rather than a lock. The Set of Rush leaves it, and it is the only thing in that set, so it has to be worth carrying on its own.
A24: ATK_DISGUST | B24: Sour Note | C24: DISGUST | D24: 12 | E24: DAMAGE | F24: 14 | G24: 0 | H24: 1 | I24: ROT | J24: ENEMY | K24: SINGLE | L24: 0 | M24: 0 | N24: 0 | O24: 0 | P24: 0 | Q24: 0 | R24: 0 | S24: 0 | T24: 1 | U24: 1 | V24: 3 | W24: Attack. Barely stings, and cracks the outermost {LAYER}. | X24: 0 | AB24: 0 | AC24: 0 | AG24: LOWEST_MS | AH24: COMMON | AJ24: 1 | AK24: =ROUND(G24*0.6 + N24*0.4 + P24*0.7 + Q24*8 + ABS(L24)*0.3, 0) | AL24: =IFERROR(D24-AG24,"") | AM24: A fifth of a Heated Punch. It exists so a Disgust unit has something to do with a slot it cannot afford a debuff for, not because anyone should fear it.
A25: TAINT | B25: Spoilage | C25: DISGUST | D25: 18 | E25: DAMAGE | F25: 10 | G25: 0 | H25: 1 | I25: ROT | J25: ENEMY | K25: SINGLE | L25: 0 | M25: 0 | N25: 0 | O25: 0 | P25: 0 | Q25: 0 | R25: 0 | S25: 0 | T25: 1 | U25: 1 | V25: 3 | W25: Attack. Chips, and holds *1* broken {LAYER} down for a turn. | X25: 0 | AA25: NO_REGEN | AB25: 0 | AC25: 1 | AG25: LOWEST_MS | AH25: COMMON | AJ25: 1 | AK25: =ROUND(G25*0.6 + N25*0.4 + P25*0.7 + Q25*8 + ABS(L25)*0.3, 0) | AL25: =IFERROR(D25-AG25,"") | AM25: The second ability to both hit and hang a status (see DRUG_HIT). Ten damage is nothing; the point is that the layer it breaks does not come back this round.
A26: SELF_RESPECT | B26: Self-Respect | C26: DISGUST | D26: 35 | E26: HEAL | F26: 45 | G26: 0 | H26: 0 | I26: SHIELD | J26: SELF | K26: SINGLE | L26: 0 | M26: 0 | N26: 0 | O26: 0 | P26: 0 | Q26: 0 | R26: 0 | S26: 0 | T26: 1 | U26: 3 | V26: 1 | W26: Restore. Takes back *45* {MS}. Once a fight. | X26: 0 | AB26: 0 | AC26: 0 | AG26: SELF | AH26: COMMON | AJ26: 1 | AK26: =ROUND(G26*0.6 + N26*0.4 + P26*0.7 + Q26*8 + ABS(L26)*0.3, 0) | AL26: =IFERROR(D26-AG26,"") | AM26: THE FIRST HEAL THE PLAYER HAS. Disgust is the right colour for it: the set is otherwise entirely about what you cannot stand in somebody else, and this is the same feeling turned around. One use and a three-turn cooldown, so it is a decision about WHEN rather than a tap you fall back on - 45 is most of a heavy hit, and spending it early because the bar looked low is the mistake it is designed to allow. `power` is the amount, as it is for every other kind; the sheet's `heal` column is still planned and using it would put this one ability's magnitude in a different cell from everybody else's.
A27: NAUSEA | B27: Turn the Stomach | C27: DISGUST | D27: 30 | E27: DEBUFF | F27: 0 | G27: 0 | H27: 0 | I27: ROT | J27: ENEMY | K27: SINGLE | L27: 0 | M27: 0 | N27: 0 | O27: 0 | P27: 0 | Q27: 0 | R27: 0 | S27: 0 | T27: 1 | U27: 1 | V27: 2 | W27: Debuff. Target *misses* attacks AND turns one on *itself* for *2 turns*. | X27: 0 | AA27: NAUSEOUS | AB27: 0 | AC27: 2 | AG27: LOWEST_MS | AH27: COMMON | AJ27: 1 | AK27: =ROUND(G27*0.6 + N27*0.4 + P27*0.7 + Q27*8 + ABS(L27)*0.3, 0) | AL27: =IFERROR(D27-AG27,"") | AM27: The most expensive debuff in the game and worth it: two live levers at once, so it costs the target accuracy and stamina in the same breath.
A28: SPOIL | B28: Let It Rot | C28: DISGUST | D28: 32 | E28: DEBUFF | F28: 0 | G28: 0 | H28: 0 | I28: ROT | J28: ENEMY | K28: SINGLE | L28: 0 | M28: 0 | N28: 0 | O28: 0 | P28: 0 | Q28: 0 | R28: 0 | S28: 0 | T28: 1 | U28: 1 | V28: 2 | W28: Debuff. *3* broken {LAYERS} stay broken, and nothing goes your way, for *3 turns*. | X28: 0 | AA28: SPOILED | AB28: 0 | AC28: 3 | AG28: LOWEST_MS | AH28: COMMON | AJ28: 1 | AK28: =ROUND(G28*0.6 + N28*0.4 + P28*0.7 + Q28*8 + ABS(L28)*0.3, 0) | AL28: =IFERROR(D28-AG28,"") | AM28: Longer than anything else and the only status that touches crit odds. It does no damage whatsoever - it simply makes the next three turns worse than they should be.
A29: SELF_HARM | B29: Self Harm | D29: 0 | E29: SELFHARM | F29: 25 | G29: 0 | H29: 0 | I29: WARN | J29: SELF | K29: SINGLE | L29: 0 | M29: 0 | N29: 0 | O29: 0 | P29: 0 | Q29: 0 | R29: 0 | S29: 0 | T29: 1 | U29: 0 | V29: 0 | W29: Status. Forced by {OVERLOAD}; costs you {MS}. | X29: 0 | AB29: 0 | AC29: 0 | AG29: SELF | AH29: OVERLOAD | AJ29: 1 | AK29: =ROUND(G29*0.6 + N29*0.4 + P29*0.7 + Q29*8 + ABS(L29)*0.3, 0) | AL29: =IFERROR(D29-AG29,"") | AM29: OVERLOAD ONLY. Forced into your line when Charge passes your ceiling. Cannot be moved or removed.
A30: FEED | B30: Feed | D30: 0 | E30: FEED | F30: 30 | G30: 0 | H30: 0 | I30: DROP | J30: ENEMY | K30: SINGLE | L30: 0 | M30: 0 | N30: 0 | O30: 0 | P30: 0 | Q30: 0 | R30: 0 | S30: 0 | T30: 1 | U30: 0 | V30: 0 | W30: Status. Forced by {OVERLOAD}; *heals* your opponent. | X30: 0 | AB30: 0 | AC30: 0 | AG30: AS_WRITTEN | AH30: OVERLOAD | AJ30: 1 | AK30: =ROUND(G30*0.6 + N30*0.4 + P30*0.7 + Q30*8 + ABS(L30)*0.3, 0) | AL30: =IFERROR(D30-AG30,"") | AM30: OVERLOAD ONLY. Heals your opponent. Cannot be moved or removed.

Sheet loadouts
A1: One Loadout per emotion; the player carries `equippedSlots` of them into a battle (units.loadouts). A Loadout may hold any ability whose emotion set includes its own emotion — see abilities.emotions for hybrids. Blank slots render as empty.
A3: id | B3: emotion | C3: name | D3: slot1 | E3: slot2 | F3: slot3 | G3: slot4 | H3: tier | I3: ec_mod | J3: passive | K3: cost | L3: trade_in | M3: enabled | N3: notes
A4: LIVE | B4: LIVE | C4: LIVE | D4: LIVE | E4: LIVE | F4: LIVE | G4: LIVE | H4: LIVE | I4: LIVE | J4: LIVE | K4: LIVE | L4: LIVE | M4: LIVE | N4: planned
A5: LO_ANGER | B5: ANGER | C5: Anger | D5: ATK_ANGER | E5: HVY_ANGER | F5: GEN_ANGER | H5: 1 | I5: 0 | M5: 1
A6: LO_SADNESS | B6: SADNESS | C6: Sadness | D6: ATK_SADNESS | E6: HVY_SADNESS | F6: INFLICT_SAD | H6: 1 | I6: 0 | M6: 1
A7: LO_JOY | B7: JOY | C7: Joy | D7: ATK_JOY | E7: HVY_JOY | F7: GEN_JOY | H7: 1 | I7: 0 | M7: 1
A8: LO_DISGUST | B8: DISGUST | C8: Disgust | D8: GEN_DISGUST | E8: ROT | F8: SELF_RESPECT | H8: 1 | I8: 0 | M8: 1 | N8: Grow a layer, rot theirs, and pick yourself back up. The only set carrying a heal, which is most of the reason to take it.
A9: LO_SURPRISE | B9: SURPRISE | C9: Jolt | D9: MID_SURPRISE | H9: 1 | I9: 0 | J9: PAS_JOLT | M9: 1 | N9: One attack and one passive, deliberately. Surprise is not about volume of swings - it is about what happens when one goes wrong, which is what PAS_JOLT turns into charge.
A10: LO_RUSH | B10: SURPRISE | C10: Rush | D10: DRUG_HIT | H10: 3 | I10: 0 | J10: PAS_RUSH | M10: 1 | N10: Sant Antoni's reward. Its passive turns every critical into rushCritSlots extra slots instead of critSlots - three instead of one - so a set that offers one attack is really offering a bigger line whenever a hit goes well.
A11: LO_FEAR | B11: FEAR | C11: Fear | H11: 1 | I11: 0 | M11: 1 | N11: No Fear abilities exist yet.

Sheet matchups
A1: THE SYNERGY TABLE — the main lever for designing interactions. One row per attack-emotion x layer-emotion pair. '*' is a wildcard; 'NONE' in layer_emotion means the target has no layers. When several rows match, the HIGHEST priority wins, so specific rows beat wildcards. Add a row like JOY | SADNESS | 20 | 2.0 | 0 | CATHARSIS and that pairing immediately behaves differently — no code change.
A3: attack_emotion | B3: layer_emotion | C3: priority | D3: dmg_mult | E3: ec_mult | F3: label | G3: tag_class | H3: sound | I3: rotates_layer | J3: self_ec | K3: status_apply | L3: enabled | M3: notes
A4: LIVE | B4: LIVE | C4: LIVE | D4: LIVE | E4: LIVE | F4: LIVE | G4: LIVE | H4: planned | I4: planned | J4: planned | K4: planned | L4: planned | M4: planned
A5: * | B5: * | C5: 0 | D5: 1 | E5: 0 | F5: OFF TYPE | G5: off | H5: hit | J5: 0 | L5: 1 | M5: Fallback. Every pair you do not name lands here.
A6: * | B6: NONE | C6: 5 | D6: 2 | E6: 0 | F6: EXPOSED! | G6: dmg | H6: hit | J6: 0 | L6: 1 | M6: No layers left: double damage, no charge.
A7: ANGER | B7: ANGER | C7: 10 | D7: 0.5 | E7: 1 | F7: ABSORBED! | G7: absorb | H7: absorb | J7: 0 | L7: 1 | M7: Same emotion: the layer drinks it.
A8: SURPRISE | B8: SURPRISE | C8: 10 | D8: 0.5 | E8: 1 | F8: ABSORBED! | G8: absorb | H8: absorb | J8: 0 | L8: 1 | M8: Same emotion: the layer drinks it.
A9: DISGUST | B9: DISGUST | C9: 10 | D9: 0.5 | E9: 1 | F9: ABSORBED! | G9: absorb | H9: absorb | J9: 0 | L9: 1 | M9: Same emotion: the layer drinks it.
A10: JOY | B10: JOY | C10: 10 | D10: 0.5 | E10: 1 | F10: ABSORBED! | G10: absorb | H10: absorb | J10: 0 | L10: 1 | M10: Same emotion: the layer drinks it.
A11: SADNESS | B11: SADNESS | C11: 10 | D11: 0.5 | E11: 1 | F11: ABSORBED! | G11: absorb | H11: absorb | J11: 0 | L11: 1 | M11: Same emotion: the layer drinks it.
A12: FEAR | B12: FEAR | C12: 10 | D12: 0.5 | E12: 1 | F12: ABSORBED! | G12: absorb | H12: absorb | J12: 0 | L12: 1 | M12: Same emotion: the layer drinks it.

Sheet units
A1: One row per combatant. 'layers' is outermost-first and rotates as it takes hits. 'pool' is which abilities this unit may use. Add enemies by adding rows. `drops` is what BEATING this unit may leave, as kind:amount:chance - CRYSTAL:2:0.75|SEGMENT:3:0.55|ORB:1:0.40 means up to two crystals three quarters of the time, up to three Track Segments just over half, and a Stamina Orb (which gives back orbMsPct of MaxMS) two times in five. Each is rolled on its own, so an enemy can leave everything, something, or nothing. Blank means nothing ever. `tier` is WEAK / REGULAR / STRONG: it is not a stat, it is what the enemy LOOKS like - a weak one is concentric triangles in battle and a small dart on the ride, a strong one is a seven-pointed star and a large spined shape. `spawn_lines` is where the map may produce it, as line:weight - L2:0.15|L5:0.15 means an uncommon sight on either. `*` is every line, and is what keeps a line with no units of its own from being empty. LEAVE IT BLANK for a boss: a unit the ride can never roll is one only the objectives sheet can reach. `persona` PINS this unit to one row of the dialogue sheet instead of drawing a character at random, which is what a boss needs and an anonymous commuter does not. `bg_bright` multiplies how strongly this enemy's colour lights the battle backdrop (blank or 1 is normal, 3 is three times as bright); `fx` names a flourish the fight runs around it (PAPARAZZI); `theme_opening`/`theme_loop` swap the battle music for this fight alone, and blank means the usual theme - a blank OPENING with a loop filled in simply starts on the loop. `ai_profile` is HOW IT DECIDES, as opposed to what it can do. GREEDY_MAX_DAMAGE (the default, and what every enemy used to share) takes at most one debuff a round and spends the rest of the line on damage. DEBUFF_FIRST takes every debuff it can afford that would actually land, and only then fills what is left - the difference between an enemy that occasionally inconveniences you and one whose whole idea is that it never hurts you much. `role` marks a unit as something the game treats specially: LINE_MANAGER gives it the second wind at bossPhaseAt, the shaking announcement on the platform, the two parting lines and the seven-second sink, and `theme2_loop` is the music its second phase is fought to. `scale` is how large it is drawn in battle against an ordinary enemy of its tier - 1.5 is half again, and every station boss carries it - and blank is 1.
A3: id | B3: name | C3: emotion | D3: tier | E3: max_ms | F3: start_ec_pct | G3: layers | H3: pool | I3: line_dir | J3: line_cap | K3: max_bonus_slots | L3: loadouts | M3: spawn_lines | N3: drops | O3: persona | P3: role | Q3: scale | R3: bg_bright | S3: fx | T3: theme_opening | U3: theme_loop | V3: theme2_loop | W3: ai_profile | X3: init | Y3: start_shield | Z3: max_layers_override | AA3: tags | AB3: enabled | AC3: notes
A4: LIVE | B4: LIVE | C4: LIVE | D4: LIVE | E4: LIVE | F4: LIVE | G4: LIVE | H4: LIVE | I4: LIVE | J4: LIVE | K4: LIVE | L4: LIVE | M4: LIVE | N4: LIVE | O4: LIVE | P4: LIVE | Q4: LIVE | R4: LIVE | S4: LIVE | T4: LIVE | U4: LIVE | V4: LIVE | W4: LIVE | X4: planned | Y4: planned | Z4: planned | AA4: planned | AB4: planned | AC4: planned
A5: player | B5: You | E5: 400 | F5: 0.5 | G5: JOY|SADNESS | H5: ATK_ANGER|ATK_SADNESS|ATK_JOY|DEFEND|RECHARGE|HVY_ANGER|HVY_SADNESS|HVY_JOY|GEN_DISGUST|GEN_ANGER|ROT|INFLICT_SAD | I5: 1 | J5: 3 | K5: 6 | L5: LO_ANGER|LO_SADNESS|LO_JOY | X5: 10 | Y5: 0 | AA5: PLAYER | AB5: 1
A6: enemy | B6: The Commuter | C6: ANGER | D6: REGULAR | E6: 250 | F6: 0.4 | G6: ANGER|ANGER|SADNESS | H6: ATK_ANGER|ATK_SADNESS|ATK_JOY|DEFEND|RECHARGE|HVY_ANGER|HVY_SADNESS|HVY_JOY|BLIND | I6: -1 | J6: 3 | K6: 6 | M6: L1:1.2|*:0.75 | N6: CRYSTAL:2:0.75|SEGMENT:3:0.55|ORB:1:0.40 | W6: GREEDY_MAX_DAMAGE | X6: 8 | Y6: 0 | AA6: ENEMY | AB6: 1 | AC6: AI reads the matchups sheet, so retuning it retunes the AI. `drops` is what beating this one may leave. The `*` in spawn_lines is what stops L3, L4 and L6 being empty of enemies until they have units of their own — the Commuter rides every line, which is the joke and also the fallback.
A7: enemy_anger_strong | B7: The Enforcer | C7: ANGER | D7: STRONG | E7: 330 | F7: 0.5 | G7: ANGER|ANGER|ANGER|SADNESS | H7: ATK_ANGER|HVY_ANGER|GEN_ANGER|BLIND|ATK_SADNESS|DEFEND|RECHARGE | I7: -1 | J7: 3 | K7: 6 | M7: L1:0.14 | N7: CRYSTAL:3:0.85|SEGMENT:4:0.70|ORB:1:0.55 | W7: GREEDY_MAX_DAMAGE | X7: 8 | Y7: 0 | AA7: ENEMY | AB7: 1 | AC7: Anger, turned up: one more layer than the Commuter and a third more stamina, and its pool is nearly all Anger, so an Anger-layered player is drinking most of it while anyone else is not.
A8: enemy_surprise | B8: The Interruption | C8: SURPRISE | D8: REGULAR | E8: 240 | F8: 0.4 | G8: SURPRISE|SURPRISE|ANGER | H8: ATK_SURPRISE|HVY_SURPRISE|STARTLE|ATK_ANGER|DEFEND|RECHARGE | I8: -1 | J8: 3 | K8: 6 | M8: L2:1.2 | N8: CRYSTAL:2:0.75|SEGMENT:3:0.55|ORB:1:0.40 | W8: GREEDY_MAX_DAMAGE | X8: 8 | Y8: 0 | AA8: ENEMY | AB8: 1 | AC8: L2's own. Slightly under the Commuter on stamina because STARTLE is worth more than it costs when it lands.
A9: enemy_surprise_strong | B9: The Reversal | C9: SURPRISE | D9: STRONG | E9: 320 | F9: 0.5 | G9: SURPRISE|SURPRISE|SURPRISE|JOY | H9: ATK_SURPRISE|HVY_SURPRISE|STARTLE|GEN_ANGER|ATK_JOY|DEFEND|RECHARGE | I9: -1 | J9: 3 | K9: 6 | M9: L2:0.12 | N9: CRYSTAL:3:0.85|SEGMENT:4:0.70|ORB:1:0.55 | W9: GREEDY_MAX_DAMAGE | X9: 8 | Y9: 0 | AA9: ENEMY | AB9: 1 | AC9: Three Surprise layers deep. GEN_ANGER is in the pool so it can grow a layer that does NOT absorb Surprise, which is the counter to a player who came dressed for it.
A10: enemy_sadness_weak | B10: The Straggler | C10: SADNESS | D10: WEAK | E10: 150 | F10: 0.3 | G10: SADNESS|SADNESS | H10: ATK_SADNESS|INFLICT_SAD|DEFEND|RECHARGE | I10: -1 | J10: 2 | K10: 4 | M10: L2:0.6|L5:0.7 | N10: CRYSTAL:1:0.45|SEGMENT:2:0.40 | W10: GREEDY_MAX_DAMAGE | X10: 8 | Y10: 0 | AA10: ENEMY | AB10: 1 | AC10: No heavy in the pool, on purpose: a WEAK enemy chips. Two slots, two layers, and INFLICT_SAD is the one thing it can do that you will remember. RARE EVEN AT HOME — the sheet says L5 at 0.15, not 1.0, because it was asked for as an uncommon sight on both its lines. Raise the L5 cell to make it Line 5's regular.
A11: enemy_joy_weak | B11: The Reveller | C11: JOY | D11: WEAK | E11: 150 | F11: 0.3 | G11: JOY|JOY | H11: ATK_JOY|GEN_JOY|DEFEND|RECHARGE | I11: -1 | J11: 2 | K11: 4 | M11: L2:0.6|L4:0.7 | N11: CRYSTAL:1:0.45|SEGMENT:2:0.40 | W11: GREEDY_MAX_DAMAGE | X11: 8 | Y11: 0 | AA11: ENEMY | AB11: 1 | AC11: On L2 because that is where the wrong people end up, and on L4 because that is where the right ones do. It is the same reveller either way; only the line around it changes what that means.
A12: enemy_joy | B12: The Celebrant | C12: JOY | D12: REGULAR | E12: 245 | F12: 0.4 | G12: JOY|JOY|SURPRISE | H12: ATK_JOY|HVY_JOY|GEN_JOY|ATK_SURPRISE|DEFEND|RECHARGE | I12: -1 | J12: 3 | K12: 6 | M12: L4:1.2 | N12: CRYSTAL:2:0.75|SEGMENT:3:0.55|ORB:1:0.40 | W12: GREEDY_MAX_DAMAGE | X12: 8 | Y12: 0 | AA12: ENEMY | AB12: 1 | AC12: L4's regular, and the counterpart to the Commuter on L1. The SURPRISE layer under two of Joy is what stops a Joy-dressed player drinking the whole fight.
A13: enemy_joy_strong | B13: The Euphoric | C13: JOY | D13: STRONG | E13: 325 | F13: 0.5 | G13: JOY|JOY|JOY|SURPRISE | H13: ATK_JOY|HVY_JOY|GEN_JOY|ATK_SURPRISE|STARTLE|DEFEND|RECHARGE | I13: -1 | J13: 3 | K13: 6 | M13: L4:0.12 | N13: CRYSTAL:3:0.85|SEGMENT:4:0.70|ORB:1:0.55 | W13: GREEDY_MAX_DAMAGE | X13: 8 | Y13: 0 | AA13: ENEMY | AB13: 1 | AC13: Joy with nothing holding it back. HVY_JOY is the hardest single hit in the game and this is the only ordinary enemy carrying it, which is the whole of its threat - a long charge you can see coming and have to decide what to do about.
A14: enemy_disgust_strong | B14: The Damp | C14: DISGUST | D14: STRONG | E14: 520 | F14: 0.55 | G14: DISGUST|DISGUST|SADNESS|DISGUST | H14: ATK_DISGUST|TAINT|NAUSEA|SPOIL|ROT|GEN_DISGUST|DEFEND|RECHARGE | I14: -1 | J14: 4 | K14: 6 | M14: L4:0.10 | N14: CRYSTAL:3:0.90|SEGMENT:4:0.75|ORB:2:0.60 | W14: DEBUFF_FIRST | X14: 8 | Y14: 0 | AA14: ENEMY | AB14: 1 | AC14: MORE STAMINA THAN A STATION BOSS and less damage than a weak enemy - the two facts are the same design. Six of its eight abilities are debuffs or layers, and the AI will not repeat a status the target already has (see aiDebuffChance), so it works through all four in turn: your layers held down, your aim gone, your own attacks turned on you, your crits gone. It cannot kill you quickly. It can make the rest of the ride miserable, and it takes a very long time to shift.
A15: boss_fondo | B15: The Terminus | C15: ANGER | D15: STRONG | E15: 344 | F15: 0.55 | G15: ANGER|ANGER|ANGER | H15: ATK_ANGER|HVY_ANGER|GEN_ANGER|BLIND|DEFEND|RECHARGE | I15: -1 | J15: 4 | K15: 6 | N15: CRYSTAL:4:1.0|SEGMENT:4:0.80|ORB:2:0.70 | O15: The Terminus | Q15: 1.5 | W15: GREEDY_MAX_DAMAGE | X15: 8 | Y15: 0 | AA15: ENEMY | AB15: 1 | AC15: The end of Line 1. PURE TYPE on purpose: an Anger-layered player drinks half of this, which is exactly the trade the armor it leaves is offering. It used to mirror that armor exactly - four layers and 430 stamina - which was tidy and much too hard; three layers and a fifth less stamina is the same fight without the wall.
A16: boss_sant_antoni | B16: The Comedown | C16: SURPRISE | D16: STRONG | E16: 320 | F16: 0.55 | G16: SURPRISE|SURPRISE|JOY | H16: ATK_SURPRISE|HVY_SURPRISE|MID_SURPRISE|STARTLE|GEN_JOY|DEFEND|RECHARGE | I16: -1 | J16: 4 | K16: 6 | N16: CRYSTAL:4:1.0|SEGMENT:4:0.80|ORB:2:0.70 | O16: The Comedown | Q16: 1.5 | W16: GREEDY_MAX_DAMAGE | X16: 8 | Y16: 0 | AA16: ENEMY | AB16: 1 | AC16: Leaves the Set of Rush. Its own pool is what the set is not: volume. The reward for beating a thing that swings six times is one ability that swings once and staggers. The layer it LOST was the innermost Surprise - the JOY one is kept deliberately, because it is the layer a player who came dressed for Surprise cannot drink, and it is the only thing making the queue a puzzle rather than a wall.
A17: boss_line_manager | B17: The Line Manager | C17: JOY | D17: STRONG | E17: 520 | F17: 0.6 | G17: JOY|JOY|JOY|SURPRISE|JOY | H17: ATK_JOY|HVY_JOY|GEN_JOY|ATK_SURPRISE|STARTLE|DEFEND|RECHARGE | I17: -1 | J17: 4 | K17: 6 | N17: CRYSTAL:5:1.0|SEGMENT:5:0.90|ORB:2:0.80 | O17: The Line Manager | P17: LINE_MANAGER | Q17: 1.5 | R17: 3 | S17: PAPARAZZI | U17: audio/line-manager.m4a | V17: audio/line-manager-phase2.m4a | W17: GREEDY_MAX_DAMAGE | X17: 8 | Y17: 0 | AA17: ENEMY | AB17: 1 | AC17: THE KEY TO LINE 4 IS BEHIND HER. Five layers, nearly all Joy, because she is not defending a position - she is defending a mood, and every hit that is not Joy is someone ruining it. `bg_bright` triples the backdrop tint so her fight is lit like a rooftop rather than a tunnel, `fx` fires the camera flashes, and the two theme columns swap the music out for hers alone.

Sheet dialogue
A1: What each enemy says. states: INTRO (battle start) - WINNING (player drops below 20% MS) - LOSING (this enemy drops below 20% MS) - DEFEAT (this enemy dies). A battle picks one persona at random from the rows matching the enemy's emotion, so the same enemy type speaks differently each run. `tier` narrows that: a WEAK or STRONG enemy uses only the rows carrying its own tier, and everything else uses the rows where tier is BLANK. Blank means ANY tier, not 'no tier'. Give a new persona all four states or it will fall silent at the moment it is missing.
A3: emotion | B3: persona | C3: state | D3: line | E3: tier | F3: enabled | G3: notes
A4: LIVE | B4: LIVE | C4: LIVE | D4: LIVE | E4: LIVE | F4: planned | G4: planned
A5: ANGER | B5: The Evicted | C5: INTRO | D5: Thirty years in this flat and they sell it to a fund! I'LL BURN IT DOWN WITH YOU IN IT! | F5: 1
A6: ANGER | B6: The Evicted | C6: WINNING | D6: Choke on the ashes! CHOKE ON THEM! | F6: 1
A7: ANGER | B7: The Evicted | C7: LOSING | D7: No... my things... my life... | F7: 1
A8: ANGER | B8: The Evicted | C8: DEFEAT | D8: Just let me... lock the door... one last time. | F8: 1
A9: ANGER | B9: The Exploited | C9: INTRO | D9: Fourteen hours biking in the rain for three euros! I'LL BREAK YOUR FUCKING LEGS! | F9: 1
A10: ANGER | B10: The Exploited | C10: WINNING | D10: Take your luxury takeout and choke on it! | F10: 1
A11: ANGER | B11: The Exploited | C11: LOSING | D11: My bike... I can't afford to fix my bike... | F11: 1
A12: ANGER | B12: The Exploited | C12: DEFEAT | D12: The app... it says I'm deactivated... | F12: 1
A13: ANGER | B13: The Betrayed | C13: INTRO | D13: You think a text message makes up for six months of lies?! I'LL TEAR YOUR THROAT OUT! | F13: 1
A14: ANGER | B14: The Betrayed | C14: WINNING | D14: Look at me! Look at me when I'm screaming at you! | F14: 1
A15: ANGER | B15: The Betrayed | C15: LOSING | D15: Stop deflecting... stop making me the crazy one! | F15: 1
A16: ANGER | B16: The Betrayed | C16: DEFEAT | D16: I just... wanted the truth. | F16: 1
... A124: SURPRISE | B124: The Ghost | C124: DEFEAT | D124: I died... I died under the metro... | F124: 1
A125: ANGER | B125: The Bailiff | C125: INTRO | D125: I have the paper, I have the locks and I have all morning. OPEN IT. | E125: STRONG | F125: 1
A126: ANGER | B126: The Bailiff | C126: WINNING | D126: Everything in here belongs to someone else now. Including you. | E126: STRONG | F126: 1
A127: ANGER | B127: The Bailiff | C127: LOSING | D127: I'm just doing my job — I'M JUST DOING MY JOB! | E127: STRONG | F127: 1
A128: ANGER | B128: The Bailiff | C128: DEFEAT | D128: There's another twelve on the list today. Someone else will come. | E128: STRONG | F128: 1
A129: ANGER | B129: The Riot Line | C129: INTRO | D129: Disperse. You have been warned. YOU HAVE BEEN WARNED! | E129: STRONG | F129: 1
A130: ANGER | B130: The Riot Line | C130: WINNING | D130: Nobody filmed this. Nobody ever films this. | E130: STRONG | F130: 1
A131: ANGER | B131: The Riot Line | C131: LOSING | D131: Hold the line... hold the LINE... | E131: STRONG | F131: 1
A132: ANGER | B132: The Riot Line | C132: DEFEAT | D132: Badge number... nobody ever asks for the badge number. | E132: STRONG | F132: 1
A133: ANGER | B133: The Developer | C133: INTRO | D133: Forty families out by Friday and a rooftop pool by spring. Try and stop me. | E133: STRONG | F133: 1
A134: ANGER | B134: The Developer | C134: WINNING | D134: This whole barri is already sold. You're standing in a render. | E134: STRONG | F134: 1
A135: ANGER | B135: The Developer | C135: LOSING | D135: The permits — who talked to the press about the permits?! | E135: STRONG | F135: 1
A136: ANGER | B136: The Developer | C136: DEFEAT | D136: It was going to be beautiful... | E136: STRONG | F136: 1
... A210: JOY | B210: The Line Manager | C210: DEFEAT2 | D210: ...it was such a good year. It was such a good, good year. | E210: BOSS | F210: 1

Sheet prompts
A1: The cue above the attack line. One is picked at random each turn.
A3: id | B3: text | C3: enabled | D3: notes
A4: LIVE | B4: LIVE | C4: LIVE | D4: planned
A5: p01 | B5: Whatcha gonna do? | C5: 1
A6: p02 | B6: How did that make you feel? | C6: 1
A7: p03 | B7: Act! | C7: 1
A8: p04 | B8: R U OK? | C8: 1
A9: p05 | B9: Show them. | C9: 1
A10: p06 | B10: Say something. | C10: 1
A11: p07 | B11: Your move. | C11: 1
A12: p08 | B12: Don't just stand there. | C12: 1
A13: p09 | B13: Feel it. | C13: 1
A14: p10 | B14: What now? | C14: 1
A15: p11 | B15: Answer that. | C15: 1
A16: p12 | B16: Let it out. | C16: 1
... A19: p15 | B19: Do something. | C19: 1

Sheet moments
A1: Title-screen mood line: "Barcelona, <weekday>, <phrase>." day is MON..SUN or * for any. Hours are Barcelona local, to_hour exclusive; a band may wrap past midnight. Highest priority wins, ties are random.
A3: id | B3: day | C3: from_hour | D3: to_hour | E3: phrase | F3: priority | G3: enabled | H3: notes
A4: LIVE | B4: LIVE | C4: LIVE | D4: LIVE | E4: LIVE | F4: LIVE | G4: LIVE | H4: planned
A5: dawn_1 | B5: * | C5: 5 | D5: 7 | E5: the first light is still deciding | F5: 0 | G5: 1
A6: dawn_2 | B6: * | C6: 5 | D6: 7 | E6: nobody has spoken yet today | F6: 0 | G6: 1
A7: morn_1 | B7: * | C7: 7 | D7: 10 | E7: early morning | F7: 0 | G7: 1
A8: morn_2 | B8: * | C8: 7 | D8: 10 | E8: the early carriages are full of unfinished sleep | F8: 0 | G8: 1
A9: morn_3 | B9: * | C9: 7 | D9: 10 | E9: everyone is already late | F9: 0 | G9: 1
A10: mid_1 | B10: * | C10: 10 | D10: 13 | E10: middle of the day | F10: 0 | G10: 1
A11: mid_2 | B11: * | C11: 10 | D11: 13 | E11: the light is flat and honest | F11: 0 | G11: 1
A12: noon_1 | B12: * | C12: 13 | D12: 16 | E12: all afternoon ahead | F12: 0 | G12: 1
A13: noon_2 | B13: * | C13: 13 | D13: 16 | E13: the long slow part of the day | F13: 0 | G13: 1
A14: late_1 | B14: * | C14: 16 | D14: 19 | E14: the afternoon is running out | F14: 0 | G14: 1
A15: late_2 | B15: * | C15: 16 | D15: 19 | E15: everyone is going somewhere they did not choose | F15: 0 | G15: 1
A16: dusk_1 | B16: * | C16: 19 | D16: 21 | E16: somber twilight | F16: 0 | G16: 1
... A32: sun_dusk | B32: SUN | C32: 19 | D32: 24 | E32: sunday dusk, and monday already breathing on it | F32: 2 | G32: 1

Sheet layer_types
A1: RESERVED. Layers are plain emotions today — units.layers holds emotion ids. This sheet exists for when a layer needs properties of its own (taking several hits to break, doing something when it breaks, or granting a passive while it is outermost).
A3: id | B3: emotion | C3: display_name | D3: durability | E3: on_break_effect | F3: on_break_value | G3: passive_effect | H3: passive_value | I3: regrow_delay_ms | J3: tags | K3: enabled | L3: notes
A4: planned | B4: planned | C4: planned | D4: planned | E4: planned | F4: planned | G4: planned | H4: planned | I4: planned | J4: planned | K4: planned | L4: planned
A5: EXAMPLE_BRITTLE_ANGER | B5: ANGER | C5: Brittle Anger | D5: 1 | E5: EC_TO_OWNER | F5: 10 | G5: DMG_TAKEN_MULT | H5: 1.25 | I5: 380 | J5: EXAMPLE | K5: 0 | L5: EXAMPLE ROW — shows the intended format. enabled=0, so it is ignored.

Sheet status_effects
A1: One row per status. Abilities apply these by id through status_apply / status_duration. Add a status by adding a row and teaching Kinds what reads it.
A3: id | B3: name | C3: duration | D3: icon | E3: color | F3: blurb | G3: block_regen | H3: miss_chance | I3: self_hits | J3: crit_mult | K3: dmg_taken_mult | L3: dmg_dealt_mult | M3: ec_gain_mult | N3: ms_per_turn | O3: ec_per_turn | P3: blocks_actions | Q3: stacking | R3: max_stacks | S3: enabled | T3: notes
A4: LIVE | B4: LIVE | C4: LIVE | D4: LIVE | E4: LIVE | F4: LIVE | G4: LIVE | H4: LIVE | I4: LIVE | J4: LIVE | K4: planned | L4: planned | M4: planned | N4: planned | O4: planned | P4: planned | Q4: planned | R4: planned | S4: LIVE | T4: planned
A5: NO_REGEN | B5: Rotting | C5: 2 | D5: ROT | E5: #56a36a | F5: *2* of your broken {LAYERS} are being held down. They stay broken until this wears off. | G5: 2 | H5: 0 | I5: 0 | J5: 0 | K5: 1 | L5: 1 | M5: 1 | N5: 0 | O5: 0 | P5: 0 | Q5: REFRESH | R5: 1 | S5: 1 | T5: Holds this many broken layers down: they stay broken while it lasts.
A6: SAD | B6: Sad | C6: 2 | D6: DROP | E6: #3d66c1 | F6: At the end of every round one of your own attacks is turned *on yourself*. | G6: 0 | H6: 0 | I6: 1 | J6: 0 | K6: 1 | L6: 1 | M6: 1 | N6: 0 | O6: 0 | P6: 0 | Q6: REFRESH | R6: 1 | S6: 1 | T6: Each round end the victim turns one of its OWN attacks on itself.
A7: OVERLOAD | B7: Overload | C7: 0 | D7: WARN | E7: #e53859 | F7: Your {EC} is over your {MS}. Your line is being invaded until you burn it down. | G7: 0 | H7: 0 | I7: 0 | J7: 0 | K7: 1 | L7: 1 | M7: 1 | N7: 0 | O7: 0 | P7: 0 | Q7: REFRESH | R7: 1 | S7: 1 | T7: DERIVED, not timed: it lasts while ec > ms, so it is never stored in unit.statuses.
A8: BLINDED | B8: Blinded | C8: 2 | D8: EYE | E8: #e53859 | F8: {ANGER} has blotted out your aim. *Half* of your attacks miss outright. | G8: 0 | H8: 0.5 | I8: 0 | J8: 0 | K8: 1 | L8: 1 | M8: 1 | N8: 0 | O8: 0 | P8: 0 | Q8: REFRESH | R8: 1 | S8: 1 | T8: The victim fluffs this fraction of its attacks.
A9: RATTLED | B9: Rattled | C9: 2 | D9: BURST | E9: #724082 | F9: {SURPRISE} came from nowhere. *A third* of your attacks go wide. | G9: 0 | H9: 0.35 | I9: 0 | J9: 0 | K9: 1 | L9: 1 | M9: 1 | N9: 0 | O9: 0 | P9: 0 | Q9: REFRESH | R9: 1 | S9: 1 | T9: Surprise's own miss status. missChance() takes the HIGHEST of everything on a unit rather than summing, so Rattled and Blinded together are just Blinded.
A10: NAUSEOUS | B10: Nauseous | C10: 2 | D10: ROT | E10: #56a36a | F10: You cannot keep anything down. *Two in five* of your attacks go wide, and one of them comes back at *you* every round. | G10: 0 | H10: 0.4 | I10: 1 | J10: 0 | K10: 1 | L10: 1 | M10: 1 | N10: 0 | O10: 0 | P10: 0 | Q10: REFRESH | R10: 1 | S10: 1 | T10: TWO levers at once, which is what makes it the priciest debuff in the game: it is Blinded and Sad in a single slot, a little weaker at each than either is alone.
A11: SPOILED | B11: Spoiled | C11: 3 | D11: ROT | E11: #3f7a52 | F11: *3* of your broken {LAYERS} are being held down, and nothing is going your way. | G11: 3 | H11: 0 | I11: 0 | J11: -0.045 | K11: 1 | L11: 1 | M11: 1 | N11: 0 | O11: 0 | P11: 0 | Q11: REFRESH | R11: 1 | S11: 1 | T11: The only status that moves crit odds. -0.045 against a base critChance of 0.05 leaves half a percent - not quite never, which is worse to play against than never.
A12: DIZZY | B12: Dizzy | C12: 1 | D12: BURST | E12: #9a6bb0 | F12: The carriage is still moving without you. *Half* of your attacks miss outright. | G12: 0 | H12: 0.5 | I12: 0 | J12: 0 | K12: 1 | L12: 1 | M12: 1 | N12: 0 | O12: 0 | P12: 0 | Q12: REFRESH | R12: 1 | S12: 1 | T12: Blinded's miss rate for a SINGLE turn - what Drug Hit leaves behind. The whole difference between this and BLINDED is how long you live with it, which is what makes a one-turn status worth costing as a basic attack rather than as a debuff.

Sheet synergies
A1: RESERVED. Line-level combos: things that depend on what else is in the line, or on what fired just before. trigger/subject/operator/value form the condition; effect/effect_value form the result. Tell me the ones you want and I will wire the vocabulary you use here.
A3: id | B3: name | C3: trigger | D3: subject | E3: operator | F3: value | G3: window | H3: effect | I3: effect_value | J3: applies_to | K3: priority | L3: enabled | M3: notes
A4: planned | B4: planned | C4: planned | D4: planned | E4: planned | F4: planned | G4: planned | H4: planned | I4: planned | J4: planned | K4: planned | L4: planned | M4: planned
A5: EXAMPLE_TRIPLE | B5: Monochrome Line | C5: LINE_CONTAINS | D5: EMOTION_COUNT | E5: >= | F5: 3 | G5: LINE | H5: DMG_MULT | I5: 1.5 | J5: ALL_STATIONS | K5: 10 | L5: 0 | M5: EXAMPLE ROW — three stations of one emotion in a line hit 50% harder. enabled=0.
A6: EXAMPLE_CHAIN | B6: Grief After Rage | C6: PREV_STATION | D6: EMOTION | E6: == | F6: ANGER | G6: STATION | H6: EC_MULT | I6: 2 | J6: THIS_STATION | K6: 20 | L6: 0 | M6: EXAMPLE ROW — a station firing straight after an Anger station gives double charge. enabled=0.

Sheet rules
A1: Global tunables. Keys are read by name — renaming one breaks whatever reads it.
A3: key | B3: value | C3: description
A4: LIVE | B4: LIVE | C4: planned
A5: lineCap | B5: 3 | C5: FALLBACK line size, used only if a unit row leaves line_cap blank.
A6: maxLayers | B6: 6 | C6: Layer slots per unit.
A7: restEc | B7: 15 | C7: Charge gained by departing with an empty line.
A8: ecBasis | B8: POWER | C8: POWER = charge figured from the ability's base power. DEALT = from damage actually dealt.
A9: noLayerDmgMult | B9: 1 | C9: Superseded by the matchups sheet; kept as a fallback.
A10: noLayerEcMult | B10: 0 | C10: Superseded by the matchups sheet; kept as a fallback.
A11: shieldRotatesLayer | B11: 0 | C11: Whether a blocked attack still rotates the layer queue.
A12: lowMsWarnPct | B12: 0.18 | C12: Below this fraction of max MS the ceiling chevron pulses red.
A13: clashSeconds | B13: 4 | C13: Length of the death sequence.
A14: layerRegenAtTurnEnd | B14: 1 | C14: Broken layers stay gone until the round ends, then regrow at the back of the queue.
A15: chargeStepMs | B15: 260 | C15: How long each charge segment holds before the next.
A16: flyMs | B16: 120 | C16: How long a station takes to fly across and strike the target.
A17: typeMs | B17: 32 | C17: Delay between letters of dialogue.
A18: dialogueHoldMs | B18: 3000 | C18: How long a finished line stays on screen before it fades.
A19: lowHpTalkPct | B19: 0.2 | C19: Fraction of max MS below which the winning / losing lines fire.
A20: overloadSlotPer | B20: 0.25 | C20: Every this-much overflow (as a fraction of max MS) forces one more corrupted slot.
... A90: ecScrollSpeed | B90: 0.0044 | C90: How fast the charge gradient drifts along the bar.
A91: themeOpening | B91: audio/theme-opening.wav | C91: Theme part 1: plays once.
A92: themeLoop | B92: audio/theme-loop.wav | C92: Theme part 2: loops for ever, scheduled to start the instant part 1 ends.
A93: musicFadeMs | B93: 900 | C93: How quickly the theme fades out when the battle ends.
A94: musicVolume | B94: 1.6 | C94: Theme level, and ABOVE 1 on purpose: this is a gain, not a percentage. The battle theme is mastered about 10 dB quieter than the map's two, so it needs lifting to sit level with them - measured busy RMS -20.1 dBFS against -9.2 and -10.6, all three now landing at -16.0. Its peak is -5.2 dBFS, so 1.6x leaves headroom and cannot clip. Lower this if the sound effects are getting buried.
A95: sfxVolume | B95: 1.05 | C95: Sound-effect level, mixed against musicVolume.
A96: layerEase | B96: 0.16 | C96: How fast layers slide to their new slot. Higher = snappier.
A97: layerWaveDelay | B97: 0.85 | C97: Phase offset per slot, so breathing travels outward in waves.
A98: layerInnerShrink | B98: 0.85 | C98: Curve of the radius falloff toward the centre.
A99: layerFill | B99: 0.42 | C99: Ring thickness as a fraction of the gap to the next slot.
A100: layerOuterThick | B100: 2 | C100: Thickness multiplier for the outermost (active) layer.
A101: layerInnerThick | B101: 0.9 | C101: Thickness multiplier for every layer behind it.
A102: layerFlashMs | B102: 50 | C102: How long a struck layer flashes white before vanishing.
A103: layerGapMs | B103: 18 | C103: Beat between the layer vanishing and it regrowing at the back.
A104: layerRegrowMs | B104: 380 | C104: How long the regrow beat holds before resolution continues.
A105: enemyRingBaseR | B105: 28 | C105: Enemy: radius of the outermost ring, in logical canvas pixels.
A106: enemyShapeWeak | B106: TRIANGLE | C106: Battle silhouette for a WEAK enemy: its layer rings are concentric TRIANGLES.
A107: enemyShapeRegular | B107: CIRCLE | C107: Battle silhouette for a REGULAR enemy. The original, and still the default for any tier the sheet does not name.
A108: enemyShapeStrong | B108: STAR | C108: Battle silhouette for a STRONG enemy: concentric stars of enemyStarPoints points.
A109: enemyStarPoints | B109: 7 | C109: Points on a STRONG enemy's star.
A110: enemyStarInner | B110: 0.62 | C110: A star's valley radius as a fraction of its point radius. LOWER = narrower, sharper points; HIGHER = a blunter, rounder star. Below about 0.45 the thin inner rings start breaking up at this canvas size.
...

Sheet sounds
A1: Every sound is synthesised at runtime — there are no audio files. wave: square | sawtooth | triangle | sine | noise. f0/f1 sweep in Hz over 'dur' ms. 'echo' is how much of the sound feeds the shared delay line. Everything runs through a bit-crusher, which is where the crunch comes from.
A3: id | B3: wave | C3: f0 | D3: f1 | E3: dur | F3: gain | G3: echo | H3: description
A4: LIVE | B4: LIVE | C4: LIVE | D4: LIVE | E4: LIVE | F4: LIVE | G4: LIVE | H4: planned
A5: tap | B5: square | C5: 980 | D5: 1460 | E5: 80 | F5: 0.46 | G5: 0.3 | H5: Adding an ability to the line.
A6: place | B6: square | C6: 620 | D6: 1760 | E6: 130 | F6: 0.4 | G6: 0.35 | H6: The station lands on your line and flashes white.
A7: resist | B7: square | C7: 880 | D7: 760 | E7: 120 | F7: 0.34 | G7: 0.3 | H7: A layer shrugs off its own emotion. Played twice, descending.
A8: hit_anger | B8: square | C8: 300 | D8: 90 | E8: 150 | F8: 0.36 | G8: 0.28 | H8: Anger lands: hard and low.
A9: hit_surprise | B9: sawtooth | C9: 1200 | D9: 300 | E9: 130 | F9: 0.3 | G9: 0.34 | H9: Surprise lands: a sharp drop.
A10: hit_disgust | B10: noise | C10: 420 | D10: 200 | E10: 180 | F10: 0.3 | G10: 0.3 | H10: Disgust lands: wet and dull.
A11: hit_joy | B11: square | C11: 900 | D11: 1800 | E11: 120 | F11: 0.3 | G11: 0.32 | H11: Joy lands: bright and rising.
A12: hit_sadness | B12: triangle | C12: 520 | D12: 180 | E12: 220 | F12: 0.3 | G12: 0.38 | H12: Sadness lands: a long fall.
A13: hit_fear | B13: noise | C13: 900 | D13: 1400 | E13: 120 | F13: 0.26 | G13: 0.4 | H13: Fear lands: a cold hiss.
A14: buff_up | B14: square | C14: 420 | D14: 1500 | E14: 260 | F14: 0.28 | G14: 0.35 | H14: Something is lifted.
A15: debuff_down | B15: sawtooth | C15: 1500 | D15: 260 | E15: 300 | F15: 0.3 | G15: 0.38 | H15: Something is dragged down.
A16: status_on | B16: noise | C16: 200 | D16: 1100 | E16: 520 | F16: 0.32 | G16: 0.5 | H16: A status takes hold.
... A56: ui_station | B56: triangle | C56: 680 | D56: 1180 | E56: 140 | F56: 0.24 | G56: 0.34 | H56: MAP: a station panel opens.

Sheet stations
A1: One row per PLACE, not per stop — an interchange is a single station several lines call at. `state` is the station's condition (blank = nothing special); it drives what the map shows and what happens to a player passing through, in either direction. x/y are schematic world units; the renderer squares every link to 45 degrees, so they only need to be roughly right.
A3: id | B3: name | C3: lines | D3: emotions | E3: state | F3: spawn | G3: fog | H3: threat | I3: diltransience | J3: x | K3: y | L3: enabled | M3: notes
A4: LIVE | B4: LIVE | C4: LIVE | D4: LIVE | E4: LIVE | F4: LIVE | G4: LIVE | H4: LIVE | I4: LIVE | J4: LIVE | K4: LIVE | L4: LIVE | M4: planned
A5: TRINITAT_NOVA | B5: Trinitat Nova | C5: L3|L4 | D5: DISGUST|JOY | J5: 414 | K5: 24 | L5: 1
A6: ROQUETES | B6: Roquetes | C6: L3 | D6: DISGUST | J6: 396 | K6: 42 | L6: 1
A7: CANYELLES | B7: Canyelles | C7: L3 | D7: DISGUST | J7: 378 | K7: 60 | L7: 1
A8: VIA_JULIA | B8: Via Júlia | C8: L4 | D8: JOY | J8: 432 | K8: 60 | L8: 1
A9: VALLDAURA | B9: Valldaura | C9: L3 | D9: DISGUST | J9: 360 | K9: 78 | L9: 1
A10: MUNDET | B10: Mundet | C10: L3 | D10: DISGUST | J10: 342 | K10: 96 | L10: 1
A11: MONTBAU | B11: Montbau | C11: L3 | D11: DISGUST | J11: 324 | K11: 114 | L11: 1
A12: LLUCMAJOR | B12: Llucmajor | C12: L4 | D12: JOY | J12: 432 | K12: 120 | L12: 1
A13: EL_COLL_LA_TEIXONERA | B13: El Coll | La Teixonera | C13: L5 | D13: SADNESS | J13: 342 | K13: 126 | L13: 1
A14: EL_CARMEL | B14: El Carmel | C14: L5 | D14: SADNESS | J14: 360 | K14: 126 | L14: 1
A15: HORTA | B15: Horta | C15: L5 | D15: SADNESS | J15: 378 | K15: 126 | L15: 1
A16: FONDO | B16: Fondo | C16: L1 | D16: ANGER | J16: 540 | K16: 126 | L16: 1
... A114: TORRASSA | B114: Torrassa | C114: L1 | D114: ANGER | J114: 126 | K114: 342 | L114: 1

Sheet metro_lines
A1: One row per line, `stations` in running order (| separated). Colour is NOT stored: it comes from the emotion, so the map cannot drift out of step with battle.
A3: id | B3: name | C3: emotion | D3: stations | E3: enabled | F3: notes
A4: LIVE | B4: LIVE | C4: LIVE | D4: LIVE | E4: LIVE | F4: planned
A5: L1 | B5: Línia 1 | C5: ANGER | D5: HOSPITAL_DE_BELLVITGE|BELLVITGE|L_HOSPITALET_AV_CARRILET|RAMBLA_JUST_OLIVERAS|CAN_SERRA|FLORIDA|TORRASSA|SANTA_EULALIA|MERCAT_NOU|PLACA_DE_SANTS|HOSTAFRANCS|ESPANYA|ROCAFORT|URGELL|UNIVERSITAT|CATALUNYA|URQUINAONA|ARC_DE_TRIOMF|MARINA|GLORIES|CLOT|NAVAS|LA_SAGRERA|FABRA_I_PUIG|SANT_ANDREU|TORRAS_I_BAGES|TRINITAT_VELLA|BARO_DE_VIVER|SANTA_COLOMA|FONDO | E5: 1
A6: L2 | B6: Línia 2 | C6: SURPRISE | D6: PARAL_LEL|SANT_ANTONI|UNIVERSITAT|PASSEIG_DE_GRACIA|TETUAN|MONUMENTAL|SAGRADA_FAMILIA|ENCANTS|CLOT|BAC_DE_RODA|SANT_MARTI|LA_PAU|VERNEDA|ARTIGUES_SANT_ADRIA|SANT_ROC|GORG|PEP_VENTURA|BADALONA_POMPEU_FABRA | E6: 1
A7: L3 | B7: Línia 3 | C7: DISGUST | D7: ZONA_UNIVERSITARIA|PALAU_REIAL|MARIA_CRISTINA|LES_CORTS|PLACA_DEL_CENTRE|SANTS_ESTACIO|ESPANYA|POBLE_SEC|PARAL_LEL|DRASSANES|LICEU|CATALUNYA|PASSEIG_DE_GRACIA|DIAGONAL|FONTANA|LESSEPS|VALLCARCA|PENITENTS|VALL_D_HEBRON|MONTBAU|MUNDET|VALLDAURA|CANYELLES|ROQUETES|TRINITAT_NOVA | E7: 1
A8: L4 | B8: Línia 4 | C8: JOY | D8: TRINITAT_NOVA|VIA_JULIA|LLUCMAJOR|MARAGALL|GUINARDO_HOSPITAL_DE_SANT_PAU|ALFONS_X|JOANIC|VERDAGUER|GIRONA|PASSEIG_DE_GRACIA|URQUINAONA|JAUME_I|BARCELONETA|CIUTADELLA_VILA_OLIMPICA|BOGATELL|LLACUNA|POBLENOU|SELVA_DE_MAR|EL_MARESME_FORUM|BESOS_MAR|BESOS|LA_PAU | E8: 1
A9: L5 | B9: Línia 5 | C9: SADNESS | D9: CORNELLA_CENTRE|GAVARRA|SANT_ILDEFONS|CAN_BOIXERES|CAN_VIDALET|PUBILLA_CASES|COLLBLANC|BADAL|PLACA_DE_SANTS|SANTS_ESTACIO|ENTENCA|HOSPITAL_CLINIC|DIAGONAL|VERDAGUER|SAGRADA_FAMILIA|SANT_PAU_DOS_DE_MAIG|CAMP_DE_L_ARPA|LA_SAGRERA|CONGRES|MARAGALL|VIRREI_AMAT|VILAPICINA|HORTA|EL_CARMEL|EL_COLL_LA_TEIXONERA|VALL_D_HEBRON | E9: 1
A10: L6 | B10: Línia 6 | C10: FEAR | D10: CATALUNYA|PROVENCA|GRACIA|SANT_GERVASI|MUNTANER|LA_BONANOVA|LES_TRES_TORRES|SARRIA | E10: 1

Sheet travel_elements
A1: What can appear around the train during a ride. `chance` is rolled per element every travelRollSecs; max_on_screen caps how many exist at once, max_per_trip how many one ride may ever produce. life_min/life_max in seconds. `drift` is speed relative to the track (>1 reads as nearer the camera). These are BASES: the target station's `spawn` column scales them, and so will weather and time of day when those exist. `unit` FORCES which units row an enemy element fights as; LEAVE IT BLANK and the map rolls one from the units that name the line being ridden in their `spawn_lines`, which is what makes Line 2 feel unlike Line 5. Fill it in only to pin one element to one enemy.
A3: id | B3: name | C3: kind | D3: motion | E3: chance | F3: max_on_screen | G3: max_per_trip | H3: life_min | I3: life_max | J3: size | K3: drift | L3: worth | M3: payload | N3: amount | O3: lock_secs | P3: unit | Q3: enabled | R3: notes
A4: LIVE | B4: LIVE | C4: LIVE | D4: LIVE | E4: LIVE | F4: LIVE | G4: LIVE | H4: LIVE | I4: LIVE | J4: LIVE | K4: LIVE | L4: LIVE | M4: LIVE | N4: LIVE | O4: LIVE | P4: LIVE | Q4: LIVE | R4: planned
A5: TRACK_SEGMENT | B5: Track Segment | C5: SEGMENT | D5: FLYBY | E5: 0.55 | F5: 5 | G5: 0 | H5: 6 | I5: 9 | J5: 11 | K5: 1.15 | L5: 1 | M5: NONE | N5: 0 | O5: 0 | Q5: 1 | R5: Bridges the link. 0 in max_per_trip means UNLIMITED. Its life is longer than a crossing on purpose: a segment must stay tappable until it leaves the bottom, never fade out mid-screen.
A6: CRYSTAL_SHARD | B6: Crystal Shard | C6: CRYSTAL | D6: FLYBY | E6: 0.10 | F6: 2 | G6: 0 | H6: 6 | I6: 9 | J6: 12 | K6: 1.0 | L6: 0 | M6: CRYSTAL | N6: 1 | O6: 0 | Q6: 1 | R6: A rotating prism in the line's own colour. Rare on purpose.
A7: EMOTIONAL_ENTITY | B7: Emotional Entity | C7: ENEMY_PASSIVE | D7: PARALLEL | E7: 0.40 | F7: 2 | G7: 4 | H7: 5.0 | I7: 15.0 | J7: 13 | K7: 0.45 | L7: 0 | M7: NONE | N7: 0 | O7: 0 | Q7: 1 | R7: Floats past. Tap to pick the fight; ignore it and it leaves. Carries the whole enemy share of a roll now that nothing forces a fight on the track.
A8: STAMINA_ORB | B8: Stamina Orb | C8: ORB | D8: FLYBY | E8: 0.1 | F8: 2 | G8: 0 | H8: 6 | I8: 9 | J8: 12 | K8: 1.0 | L8: 0 | M8: MS | N8: 10 | O8: 0 | Q8: 1 | R8: Gives back `amount` PERCENT of MaxMS. Only meaningful mid-ride, which is the only time MS moves - on the map it is restored in full anyway.
A9: ENERGY_TRIANGLE | B9: Energy Triangle | C9: ENERGY | D9: FLYBY | E9: 0.25 | F9: 3 | G9: 0 | H9: 5 | I9: 8 | J9: 12 | K9: 1.75 | L9: 0 | M9: EC | N9: 20 | O9: 0 | Q9: 1 | R9: Gives back `amount` EC flat. Falls FAST (high drift) and flashes through every emotion, because it is not any one of them. Capped so a ride can never overload the player.

Sheet items
A1: PLACEHOLDERS. Item design is not written yet — these exist so the roll-and-lose machinery has something to roll. `weight` is relative drop likelihood.
A3: id | B3: name | C3: emotion | D3: weight | E3: cost | F3: enabled | G3: notes
A4: LIVE | B4: LIVE | C4: LIVE | D4: LIVE | E4: planned | F4: LIVE | G4: planned

Sheet armor
A1: Emotional Armor. `ms_mod` is ADDED to the player's base MaxMS; layer1..layer4 are the Emotional Layers it grants in battle, outermost first (blank = none, and a gap ends the run). One passive per piece. The ceiling is `maxLayers`, not the number of columns - add layer5 here and in layersOf() the day a piece needs it. cost/trade_in are for the Wandering Store, which is not built yet.
A3: id | B3: name | C3: tier | D3: ms_mod | E3: layer1 | F3: layer2 | G3: layer3 | H3: layer4 | I3: passive | J3: cost | K3: trade_in | L3: enabled | M3: notes
A4: LIVE | B4: LIVE | C4: LIVE | D4: LIVE | E4: LIVE | F4: LIVE | G4: LIVE | H4: LIVE | I4: LIVE | J4: LIVE | K4: LIVE | L4: LIVE | M4: planned
A5: ARM_SCARS | B5: Calloused Scars | C5: 1 | D5: 80 | E5: ANGER | I5: PAS_THICKSKIN | L5: 1 | M5: Starter. One layer, and it is the one that hits back.
A6: ARM_SHELL | B6: Apathetic Shell | C6: 2 | D6: 120 | E6: DISGUST | F6: FEAR | I6: PAS_NUMB | J6: 120 DISGUST + 60 FEAR | K6: ARM_SCARS | L6: 1 | M6: Two layers. Slow to feel anything, which is the point.
A7: ARM_GLASSES | B7: Rose-Tinted Glasses | C7: 2 | D7: 60 | E7: JOY | F7: SURPRISE | I7: PAS_DENIAL | J7: 140 JOY + 40 SURPRISE | K7: ARM_SCARS | L7: 1 | M7: Least stamina, brightest layers.
